<robot name="base_link" version="1.0">
  <joint name="obj_10_z_joint" type="prismatic">
    <limit lower="-10.00000" upper="10.00000" effort="1000.00000" velocity="5.00000"/>
    <origin rpy="0.00000 0.00000 0.00000" xyz="0.00000 0.00000 0.00000"/>
    <parent link="base_link"/>
    <child link="obj_10_virtual_z_link"/>
    <axis xyz="0.00000 0.00000 1.00000"/>
  </joint>
  <joint name="obj_10_y_joint" type="prismatic">
    <limit lower="-10.00000" upper="10.00000" effort="1000.00000" velocity="5.00000"/>
    <origin rpy="0.00000 0.00000 0.00000" xyz="0.00000 0.00000 0.00000"/>
    <parent link="obj_10_virtual_z_link"/>
    <child link="obj_10_virtual_y_link"/>
    <axis xyz="0.00000 1.00000 0.00000"/>
  </joint>
  <joint name="obj_1_y_joint" type="prismatic">
    <limit lower="-10.00000" upper="10.00000" effort="1000.00000" velocity="5.00000"/>
    <origin rpy="0.00000 0.00000 0.00000" xyz="0.00000 0.00000 0.00000"/>
    <parent link="obj_1_virtual_z_link"/>
    <child link="obj_1_virtual_y_link"/>
    <axis xyz="0.00000 1.00000 0.00000"/>
  </joint>
  <joint name="obj_1_x_joint" type="prismatic">
    <limit lower="-10.00000" upper="10.00000" effort="1000.00000" velocity="5.00000"/>
    <origin rpy="0.00000 0.00000 0.00000" xyz="0.00000 0.00000 0.00000"/>
    <parent link="obj_1_virtual_y_link"/>
    <child link="obj_1_x_link"/>
    <axis xyz="1.00000 0.00000 0.00000"/>
  </joint>
  <joint name="obj_2_z_joint" type="prismatic">
    <limit lower="-10.00000" upper="10.00000" effort="1000.00000" velocity="5.00000"/>
    <origin rpy="0.00000 0.00000 0.00000" xyz="0.00000 0.00000 0.00000"/>
    <parent link="base_link"/>
    <child link="obj_2_virtual_z_link"/>
    <axis xyz="0.00000 0.00000 1.00000"/>
  </joint>
  <joint name="obj_2_y_joint" type="prismatic">
    <limit lower="-10.00000" upper="10.00000" effort="1000.00000" velocity="5.00000"/>
    <origin rpy="0.00000 0.00000 0.00000" xyz="0.00000 0.00000 0.00000"/>
    <parent link="obj_2_virtual_z_link"/>
    <child link="obj_2_virtual_y_link"/>
    <axis xyz="0.00000 1.00000 0.00000"/>
  </joint>
  <joint name="obj_2_x_joint" type="prismatic">
    <limit lower="-10.00000" upper="10.00000" effort="1000.00000" velocity="5.00000"/>
    <origin rpy="0.00000 0.00000 0.00000" xyz="0.00000 0.00000 0.00000"/>
    <parent link="obj_2_virtual_y_link"/>
    <child link="obj_2_x_link"/>
    <axis xyz="1.00000 0.00000 0.00000"/>
  </joint>
  <joint name="obj_3_z_joint" type="prismatic">
    <limit lower="-10.00000" upper="10.00000" effort="1000.00000" velocity="5.00000"/>
    <origin rpy="0.00000 0.00000 0.00000" xyz="0.00000 0.00000 0.00000"/>
    <parent link="base_link"/>
    <child link="obj_3_virtual_z_link"/>
    <axis xyz="0.00000 0.00000 1.00000"/>
  </joint>
  <joint name="obj_3_y_joint" type="prismatic">
    <limit lower="-10.00000" upper="10.00000" effort="1000.00000" velocity="5.00000"/>
    <origin rpy="0.00000 0.00000 0.00000" xyz="0.00000 0.00000 0.00000"/>
    <parent link="obj_3_virtual_z_link"/>
    <child link="obj_3_virtual_y_link"/>
    <axis xyz="0.00000 1.00000 0.00000"/>
  </joint>
  <joint name="obj_3_x_joint" type="prismatic">
    <limit lower="-10.00000" upper="10.00000" effort="1000.00000" velocity="5.00000"/>
    <origin rpy="0.00000 0.00000 0.00000" xyz="0.00000 0.00000 0.00000"/>
    <parent link="obj_3_virtual_y_link"/>
    <child link="obj_3_x_link"/>
    <axis xyz="1.00000 0.00000 0.00000"/>
  </joint>
  <joint name="obj_4_z_joint" type="prismatic">
    <limit lower="-10.00000" upper="10.00000" effort="1000.00000" velocity="5.00000"/>
    <origin rpy="0.00000 0.00000 0.00000" xyz="0.00000 0.00000 0.00000"/>
    <parent link="base_link"/>
    <child link="obj_4_virtual_z_link"/>
    <axis xyz="0.00000 0.00000 1.00000"/>
  </joint>
  <joint name="obj_4_y_joint" type="prismatic">
    <limit lower="-10.00000" upper="10.00000" effort="1000.00000" velocity="5.00000"/>
    <origin rpy="0.00000 0.00000 0.00000" xyz="0.00000 0.00000 0.00000"/>
    <parent link="obj_4_virtual_z_link"/>
    <child link="obj_4_virtual_y_link"/>
    <axis xyz="0.00000 1.00000 0.00000"/>
  </joint>
  <joint name="obj_10_x_joint" type="prismatic">
    <limit lower="-10.00000" upper="10.00000" effort="1000.00000" velocity="5.00000"/>
    <origin rpy="0.00000 0.00000 0.00000" xyz="0.00000 0.00000 0.00000"/>
    <parent link="obj_10_virtual_y_link"/>
    <child link="obj_10_x_link"/>
    <axis xyz="1.00000 0.00000 0.00000"/>
  </joint>
  <joint name="obj_4_x_joint" type="prismatic">
    <limit lower="-10.00000" upper="10.00000" effort="1000.00000" velocity="5.00000"/>
    <origin rpy="0.00000 0.00000 0.00000" xyz="0.00000 0.00000 0.00000"/>
    <parent link="obj_4_virtual_y_link"/>
    <child link="obj_4_x_link"/>
    <axis xyz="1.00000 0.00000 0.00000"/>
  </joint>
  <joint name="obj_5_z_joint" type="prismatic">
    <limit lower="-10.00000" upper="10.00000" effort="1000.00000" velocity="5.00000"/>
    <origin rpy="0.00000 0.00000 0.00000" xyz="0.00000 0.00000 0.00000"/>
    <parent link="base_link"/>
    <child link="obj_5_virtual_z_link"/>
    <axis xyz="0.00000 0.00000 1.00000"/>
  </joint>
  <joint name="obj_5_y_joint" type="prismatic">
    <limit lower="-10.00000" upper="10.00000" effort="1000.00000" velocity="5.00000"/>
    <origin rpy="0.00000 0.00000 0.00000" xyz="0.00000 0.00000 0.00000"/>
    <parent link="obj_5_virtual_z_link"/>
    <child link="obj_5_virtual_y_link"/>
    <axis xyz="0.00000 1.00000 0.00000"/>
  </joint>
  <joint name="obj_5_x_joint" type="prismatic">
    <limit lower="-10.00000" upper="10.00000" effort="1000.00000" velocity="5.00000"/>
    <origin rpy="0.00000 0.00000 0.00000" xyz="0.00000 0.00000 0.00000"/>
    <parent link="obj_5_virtual_y_link"/>
    <child link="obj_5_x_link"/>
    <axis xyz="1.00000 0.00000 0.00000"/>
  </joint>
  <joint name="obj_6_z_joint" type="prismatic">
    <limit lower="-10.00000" upper="10.00000" effort="1000.00000" velocity="5.00000"/>
    <origin rpy="0.00000 0.00000 0.00000" xyz="0.00000 0.00000 0.00000"/>
    <parent link="base_link"/>
    <child link="obj_6_virtual_z_link"/>
    <axis xyz="0.00000 0.00000 1.00000"/>
  </joint>
  <joint name="obj_6_y_joint" type="prismatic">
    <limit lower="-10.00000" upper="10.00000" effort="1000.00000" velocity="5.00000"/>
    <origin rpy="0.00000 0.00000 0.00000" xyz="0.00000 0.00000 0.00000"/>
    <parent link="obj_6_virtual_z_link"/>
    <child link="obj_6_virtual_y_link"/>
    <axis xyz="0.00000 1.00000 0.00000"/>
  </joint>
  <joint name="obj_6_x_joint" type="prismatic">
    <limit lower="-10.00000" upper="10.00000" effort="1000.00000" velocity="5.00000"/>
    <origin rpy="0.00000 0.00000 0.00000" xyz="0.00000 0.00000 0.00000"/>
    <parent link="obj_6_virtual_y_link"/>
    <child link="obj_6_x_link"/>
    <axis xyz="1.00000 0.00000 0.00000"/>
  </joint>
  <joint name="obj_7_z_joint" type="prismatic">
    <limit lower="-10.00000" upper="10.00000" effort="1000.00000" velocity="5.00000"/>
    <origin rpy="0.00000 0.00000 0.00000" xyz="0.00000 0.00000 0.00000"/>
    <parent link="base_link"/>
    <child link="obj_7_virtual_z_link"/>
    <axis xyz="0.00000 0.00000 1.00000"/>
  </joint>
  <joint name="obj_7_y_joint" type="prismatic">
    <limit lower="-10.00000" upper="10.00000" effort="1000.00000" velocity="5.00000"/>
    <origin rpy="0.00000 0.00000 0.00000" xyz="0.00000 0.00000 0.00000"/>
    <parent link="obj_7_virtual_z_link"/>
    <child link="obj_7_virtual_y_link"/>
    <axis xyz="0.00000 1.00000 0.00000"/>
  </joint>
  <joint name="obj_7_x_joint" type="prismatic">
    <limit lower="-10.00000" upper="10.00000" effort="1000.00000" velocity="5.00000"/>
    <origin rpy="0.00000 0.00000 0.00000" xyz="0.00000 0.00000 0.00000"/>
    <parent link="obj_7_virtual_y_link"/>
    <child link="obj_7_x_link"/>
    <axis xyz="1.00000 0.00000 0.00000"/>
  </joint>
  <joint name="obj_11_z_joint" type="prismatic">
    <limit lower="-10.00000" upper="10.00000" effort="1000.00000" velocity="5.00000"/>
    <origin rpy="0.00000 0.00000 0.00000" xyz="0.00000 0.00000 0.00000"/>
    <parent link="base_link"/>
    <child link="obj_11_virtual_z_link"/>
    <axis xyz="0.00000 0.00000 1.00000"/>
  </joint>
  <joint name="obj_8_z_joint" type="prismatic">
    <limit lower="-10.00000" upper="10.00000" effort="1000.00000" velocity="5.00000"/>
    <origin rpy="0.00000 0.00000 0.00000" xyz="0.00000 0.00000 0.00000"/>
    <parent link="base_link"/>
    <child link="obj_8_virtual_z_link"/>
    <axis xyz="0.00000 0.00000 1.00000"/>
  </joint>
  <joint name="obj_8_y_joint" type="prismatic">
    <limit lower="-10.00000" upper="10.00000" effort="1000.00000" velocity="5.00000"/>
    <origin rpy="0.00000 0.00000 0.00000" xyz="0.00000 0.00000 0.00000"/>
    <parent link="obj_8_virtual_z_link"/>
    <child link="obj_8_virtual_y_link"/>
    <axis xyz="0.00000 1.00000 0.00000"/>
  </joint>
  <joint name="obj_8_x_joint" type="prismatic">
    <limit lower="-10.00000" upper="10.00000" effort="1000.00000" velocity="5.00000"/>
    <origin rpy="0.00000 0.00000 0.00000" xyz="0.00000 0.00000 0.00000"/>
    <parent link="obj_8_virtual_y_link"/>
    <child link="obj_8_x_link"/>
    <axis xyz="1.00000 0.00000 0.00000"/>
  </joint>
  <joint name="obj_9_z_joint" type="prismatic">
    <limit lower="-10.00000" upper="10.00000" effort="1000.00000" velocity="5.00000"/>
    <origin rpy="0.00000 0.00000 0.00000" xyz="0.00000 0.00000 0.00000"/>
    <parent link="base_link"/>
    <child link="obj_9_virtual_z_link"/>
    <axis xyz="0.00000 0.00000 1.00000"/>
  </joint>
  <joint name="obj_9_y_joint" type="prismatic">
    <limit lower="-10.00000" upper="10.00000" effort="1000.00000" velocity="5.00000"/>
    <origin rpy="0.00000 0.00000 0.00000" xyz="0.00000 0.00000 0.00000"/>
    <parent link="obj_9_virtual_z_link"/>
    <child link="obj_9_virtual_y_link"/>
    <axis xyz="0.00000 1.00000 0.00000"/>
  </joint>
  <joint name="obj_9_x_joint" type="prismatic">
    <limit lower="-10.00000" upper="10.00000" effort="1000.00000" velocity="5.00000"/>
    <origin rpy="0.00000 0.00000 0.00000" xyz="0.00000 0.00000 0.00000"/>
    <parent link="obj_9_virtual_y_link"/>
    <child link="obj_9_x_link"/>
    <axis xyz="1.00000 0.00000 0.00000"/>
  </joint>
  <joint name="obj_11_y_joint" type="prismatic">
    <limit lower="-10.00000" upper="10.00000" effort="1000.00000" velocity="5.00000"/>
    <origin rpy="0.00000 0.00000 0.00000" xyz="0.00000 0.00000 0.00000"/>
    <parent link="obj_11_virtual_z_link"/>
    <child link="obj_11_virtual_y_link"/>
    <axis xyz="0.00000 1.00000 0.00000"/>
  </joint>
  <joint name="obj_11_x_joint" type="prismatic">
    <limit lower="-10.00000" upper="10.00000" effort="1000.00000" velocity="5.00000"/>
    <origin rpy="0.00000 0.00000 0.00000" xyz="0.00000 0.00000 0.00000"/>
    <parent link="obj_11_virtual_y_link"/>
    <child link="obj_11_x_link"/>
    <axis xyz="1.00000 0.00000 0.00000"/>
  </joint>
  <joint name="obj_12_z_joint" type="prismatic">
    <limit lower="-10.00000" upper="10.00000" effort="1000.00000" velocity="5.00000"/>
    <origin rpy="0.00000 0.00000 0.00000" xyz="0.00000 0.00000 0.00000"/>
    <parent link="base_link"/>
    <child link="obj_12_virtual_z_link"/>
    <axis xyz="0.00000 0.00000 1.00000"/>
  </joint>
  <joint name="obj_12_y_joint" type="prismatic">
    <limit lower="-10.00000" upper="10.00000" effort="1000.00000" velocity="5.00000"/>
    <origin rpy="0.00000 0.00000 0.00000" xyz="0.00000 0.00000 0.00000"/>
    <parent link="obj_12_virtual_z_link"/>
    <child link="obj_12_virtual_y_link"/>
    <axis xyz="0.00000 1.00000 0.00000"/>
  </joint>
  <joint name="obj_12_x_joint" type="prismatic">
    <limit lower="-10.00000" upper="10.00000" effort="1000.00000" velocity="5.00000"/>
    <origin rpy="0.00000 0.00000 0.00000" xyz="0.00000 0.00000 0.00000"/>
    <parent link="obj_12_virtual_y_link"/>
    <child link="obj_12_x_link"/>
    <axis xyz="1.00000 0.00000 0.00000"/>
  </joint>
  <joint name="obj_1_z_joint" type="prismatic">
    <limit lower="-10.00000" upper="10.00000" effort="1000.00000" velocity="5.00000"/>
    <origin rpy="0.00000 0.00000 0.00000" xyz="0.00000 0.00000 0.00000"/>
    <parent link="base_link"/>
    <child link="obj_1_virtual_z_link"/>
    <axis xyz="0.00000 0.00000 1.00000"/>
  </joint>
  <link name="base_link"/>
  <link name="obj_10_virtual_z_link">
    <inertial>
      <inertia ixx="0.00100" ixy="0.00000" ixz="0.00000" iyy="0.00100" iyz="0.00000" izz="0.00100"/>
      <origin rpy="0.00000 0.00000 0.00000" xyz="0.00000 0.00000 0.00000"/>
      <mass value="0.00100"/>
    </inertial>
  </link>
  <link name="obj_1_virtual_z_link">
    <inertial>
      <inertia ixx="0.00100" ixy="0.00000" ixz="0.00000" iyy="0.00100" iyz="0.00000" izz="0.00100"/>
      <origin rpy="0.00000 0.00000 0.00000" xyz="0.00000 0.00000 0.00000"/>
      <mass value="0.00100"/>
    </inertial>
  </link>
  <link name="obj_1_virtual_y_link">
    <inertial>
      <inertia ixx="0.00100" ixy="0.00000" ixz="0.00000" iyy="0.00100" iyz="0.00000" izz="0.00100"/>
      <origin rpy="0.00000 0.00000 0.00000" xyz="0.00000 0.00000 0.00000"/>
      <mass value="0.00100"/>
    </inertial>
  </link>
  <link name="obj_1_x_link">
    <collision name="obj_1_collision_1">
      <origin rpy="1.57080 0.00000 0.00000" xyz="-0.99986 3.00249 0.36746"/>
      <geometry>
        <mesh filename="../meshes/stl/Cube.002.stl" scale="1.00000 0.98000 1.00000"/>
      </geometry>
    </collision>
    <collision name="obj_1_collision_2">
      <origin rpy="1.57080 0.00000 0.00000" xyz="-1.00029 3.00249 3.38262"/>
      <geometry>
        <mesh filename="../meshes/stl/Cube.003.stl" scale="1.00000 0.98000 1.00000"/>
      </geometry>
    </collision>
    <collision name="obj_1_collision_3">
      <origin rpy="1.57080 0.00000 0.00000" xyz="-0.99964 3.19009 1.87370"/>
      <geometry>
        <mesh filename="../meshes/stl/Cube.004.stl" scale="2.00000 6.08000 1.00000"/>
      </geometry>
    </collision>
    <inertial>
      <inertia ixx="0.66551" ixy="0.00000" ixz="-0.00000" iyy="0.04842" iyz="0.00000" izz="0.65895"/>
      <origin rpy="0.00000 0.00000 0.00000" xyz="-1.00000 3.08500 1.87500"/>
      <mass value="0.50000"/>
    </inertial>
    <visual name="obj_1">
      <material name="None"/>
      <origin rpy="1.57080 0.00000 0.00000" xyz="-1.00000 3.08500 1.87500"/>
      <geometry>
        <mesh filename="../meshes/stl/luban-lock-sliding.stl" scale="0.05000 0.05000 0.05000"/>
      </geometry>
    </visual>
  </link>
  <link name="obj_2_virtual_z_link">
    <inertial>
      <inertia ixx="0.00100" ixy="0.00000" ixz="0.00000" iyy="0.00100" iyz="0.00000" izz="0.00100"/>
      <origin rpy="0.00000 0.00000 0.00000" xyz="0.00000 0.00000 0.00000"/>
      <mass value="0.00100"/>
    </inertial>
  </link>
  <link name="obj_2_virtual_y_link">
    <inertial>
      <inertia ixx="0.00100" ixy="0.00000" ixz="0.00000" iyy="0.00100" iyz="0.00000" izz="0.00100"/>
      <origin rpy="0.00000 0.00000 0.00000" xyz="0.00000 0.00000 0.00000"/>
      <mass value="0.00100"/>
    </inertial>
  </link>
  <link name="obj_2_x_link">
    <collision name="obj_2_collision_1">
      <origin rpy="1.57080 0.00000 0.00000" xyz="-1.75064 3.00249 0.36746"/>
      <geometry>
        <mesh filename="../meshes/stl/Cube.005.stl" scale="1.00000 0.98000 1.00000"/>
      </geometry>
    </collision>
    <collision name="obj_2_collision_2">
      <origin rpy="1.57080 0.00000 0.00000" xyz="-1.75107 3.00249 3.38262"/>
      <geometry>
        <mesh filename="../meshes/stl/Cube.006.stl" scale="1.00000 0.98000 1.00000"/>
      </geometry>
    </collision>
    <collision name="obj_2_collision_3">
      <origin rpy="1.57080 0.00000 0.00000" xyz="-1.75042 3.19009 1.87370"/>
      <geometry>
        <mesh filename="../meshes/stl/Cube.007.stl" scale="2.00000 6.08000 1.00000"/>
      </geometry>
    </collision>
    <inertial>
      <inertia ixx="0.66551" ixy="0.00000" ixz="0.00000" iyy="0.04842" iyz="0.00000" izz="0.65895"/>
      <origin rpy="0.00000 0.00000 0.00000" xyz="-1.75100 3.08500 1.87500"/>
      <mass value="0.50000"/>
    </inertial>
    <visual name="obj_2">
      <material name="None"/>
      <origin rpy="1.57080 0.00000 0.00000" xyz="-1.75100 3.08500 1.87500"/>
      <geometry>
        <mesh filename="../meshes/stl/luban-lock-sliding.001.stl" scale="0.05000 0.05000 0.05000"/>
      </geometry>
    </visual>
  </link>
  <link name="obj_3_virtual_z_link">
    <inertial>
      <inertia ixx="0.00100" ixy="0.00000" ixz="0.00000" iyy="0.00100" iyz="0.00000" izz="0.00100"/>
      <origin rpy="0.00000 0.00000 0.00000" xyz="0.00000 0.00000 0.00000"/>
      <mass value="0.00100"/>
    </inertial>
  </link>
  <link name="obj_3_virtual_y_link">
    <inertial>
      <inertia ixx="0.00100" ixy="0.00000" ixz="0.00000" iyy="0.00100" iyz="0.00000" izz="0.00100"/>
      <origin rpy="0.00000 0.00000 0.00000" xyz="0.00000 0.00000 0.00000"/>
      <mass value="0.00100"/>
    </inertial>
  </link>
  <link name="obj_3_x_link">
    <collision name="obj_3_collision_1">
      <origin rpy="-1.57080 0.00000 0.00000" xyz="-0.99960 1.49751 3.38254"/>
      <geometry>
        <mesh filename="../meshes/stl/Cube.008.stl" scale="1.00000 0.98000 1.00000"/>
      </geometry>
    </collision>
    <collision name="obj_3_collision_2">
      <origin rpy="-1.57080 0.00000 0.00000" xyz="-1.00002 1.49751 0.36738"/>
      <geometry>
        <mesh filename="../meshes/stl/Cube.009.stl" scale="1.00000 0.98000 1.00000"/>
      </geometry>
    </collision>
    <collision name="obj_3_collision_3">
      <origin rpy="-1.57080 0.00000 0.00000" xyz="-0.99938 1.30991 1.87630"/>
      <geometry>
        <mesh filename="../meshes/stl/Cube.010.stl" scale="2.00000 6.08000 1.00000"/>
      </geometry>
    </collision>
    <inertial>
      <inertia ixx="0.66551" ixy="-0.00000" ixz="0.00000" iyy="0.04842" iyz="0.00000" izz="0.65895"/>
      <origin rpy="0.00000 0.00000 0.00000" xyz="-1.00000 1.41500 1.87500"/>
      <mass value="0.50000"/>
    </inertial>
    <visual name="obj_3">
      <material name="None"/>
      <origin rpy="-1.57080 0.00000 0.00000" xyz="-1.00000 1.41500 1.87500"/>
      <geometry>
        <mesh filename="../meshes/stl/luban-lock-sliding.002.stl" scale="0.05000 0.05000 0.05000"/>
      </geometry>
    </visual>
  </link>
  <link name="obj_4_virtual_z_link">
    <inertial>
      <inertia ixx="0.00100" ixy="0.00000" ixz="0.00000" iyy="0.00100" iyz="0.00000" izz="0.00100"/>
      <origin rpy="0.00000 0.00000 0.00000" xyz="0.00000 0.00000 0.00000"/>
      <mass value="0.00100"/>
    </inertial>
  </link>
  <link name="obj_10_virtual_y_link">
    <inertial>
      <inertia ixx="0.00100" ixy="0.00000" ixz="0.00000" iyy="0.00100" iyz="0.00000" izz="0.00100"/>
      <origin rpy="0.00000 0.00000 0.00000" xyz="0.00000 0.00000 0.00000"/>
      <mass value="0.00100"/>
    </inertial>
  </link>
  <link name="obj_4_virtual_y_link">
    <inertial>
      <inertia ixx="0.00100" ixy="0.00000" ixz="0.00000" iyy="0.00100" iyz="0.00000" izz="0.00100"/>
      <origin rpy="0.00000 0.00000 0.00000" xyz="0.00000 0.00000 0.00000"/>
      <mass value="0.00100"/>
    </inertial>
  </link>
  <link name="obj_4_x_link">
    <collision name="obj_4_collision_1">
      <origin rpy="-1.57080 0.00000 0.00000" xyz="-1.75313 1.49751 3.38254"/>
      <geometry>
        <mesh filename="../meshes/stl/Cube.011.stl" scale="1.00000 0.98000 1.00000"/>
      </geometry>
    </collision>
    <collision name="obj_4_collision_2">
      <origin rpy="-1.57080 0.00000 0.00000" xyz="-1.75355 1.49751 0.36738"/>
      <geometry>
        <mesh filename="../meshes/stl/Cube.012.stl" scale="1.00000 0.98000 1.00000"/>
      </geometry>
    </collision>
    <collision name="obj_4_collision_3">
      <origin rpy="-1.57080 0.00000 0.00000" xyz="-1.75291 1.30991 1.87630"/>
      <geometry>
        <mesh filename="../meshes/stl/Cube.013.stl" scale="2.00000 6.08000 1.00000"/>
      </geometry>
    </collision>
    <inertial>
      <inertia ixx="0.66551" ixy="-0.00000" ixz="0.00000" iyy="0.04842" iyz="0.00000" izz="0.65895"/>
      <origin rpy="0.00000 0.00000 0.00000" xyz="-1.75100 1.41500 1.87500"/>
      <mass value="0.50000"/>
    </inertial>
    <visual name="obj_4">
      <material name="None"/>
      <origin rpy="-1.57080 0.00000 0.00000" xyz="-1.75100 1.41500 1.87500"/>
      <geometry>
        <mesh filename="../meshes/stl/luban-lock-sliding.003.stl" scale="0.05000 0.05000 0.05000"/>
      </geometry>
    </visual>
  </link>
  <link name="obj_5_virtual_z_link">
    <inertial>
      <inertia ixx="0.00100" ixy="0.00000" ixz="0.00000" iyy="0.00100" iyz="0.00000" izz="0.00100"/>
      <origin rpy="0.00000 0.00000 0.00000" xyz="0.00000 0.00000 0.00000"/>
      <mass value="0.00100"/>
    </inertial>
  </link>
  <link name="obj_5_virtual_y_link">
    <inertial>
      <inertia ixx="0.00100" ixy="0.00000" ixz="0.00000" iyy="0.00100" iyz="0.00000" izz="0.00100"/>
      <origin rpy="0.00000 0.00000 0.00000" xyz="0.00000 0.00000 0.00000"/>
      <mass value="0.00100"/>
    </inertial>
  </link>
  <link name="obj_5_x_link">
    <collision name="obj_5_collision_1">
      <origin rpy="0.00000 0.00000 1.57080" xyz="0.13204 1.87503 1.12839"/>
      <geometry>
        <mesh filename="../meshes/stl/Cube.014.stl" scale="1.00000 0.98000 1.00000"/>
      </geometry>
    </collision>
    <collision name="obj_5_collision_2">
      <origin rpy="0.00000 0.00000 1.57080" xyz="-2.88312 1.87460 1.12839"/>
      <geometry>
        <mesh filename="../meshes/stl/Cube.015.stl" scale="1.00000 0.98000 1.00000"/>
      </geometry>
    </collision>
    <collision name="obj_5_collision_3">
      <origin rpy="0.00000 0.00000 1.57080" xyz="-1.37420 1.87525 0.94079"/>
      <geometry>
        <mesh filename="../meshes/stl/Cube.016.stl" scale="2.00000 6.08000 1.00000"/>
      </geometry>
    </collision>
    <inertial>
      <inertia ixx="0.66551" ixy="0.00000" ixz="0.00000" iyy="0.04842" iyz="0.00000" izz="0.65895"/>
      <origin rpy="0.00000 0.00000 0.00000" xyz="-1.37550 1.87500 1.04588"/>
      <mass value="0.50000"/>
    </inertial>
    <visual name="obj_5">
      <material name="None"/>
      <origin rpy="0.00000 0.00000 1.57080" xyz="-1.37550 1.87500 1.04588"/>
      <geometry>
        <mesh filename="../meshes/stl/luban-lock-sliding.004.stl" scale="0.05000 0.05000 0.05000"/>
      </geometry>
    </visual>
  </link>
  <link name="obj_6_virtual_z_link">
    <inertial>
      <inertia ixx="0.00100" ixy="0.00000" ixz="0.00000" iyy="0.00100" iyz="0.00000" izz="0.00100"/>
      <origin rpy="0.00000 0.00000 0.00000" xyz="0.00000 0.00000 0.00000"/>
      <mass value="0.00100"/>
    </inertial>
  </link>
  <link name="obj_6_virtual_y_link">
    <inertial>
      <inertia ixx="0.00100" ixy="0.00000" ixz="0.00000" iyy="0.00100" iyz="0.00000" izz="0.00100"/>
      <origin rpy="0.00000 0.00000 0.00000" xyz="0.00000 0.00000 0.00000"/>
      <mass value="0.00100"/>
    </inertial>
  </link>
  <link name="obj_6_x_link">
    <collision name="obj_6_collision_1">
      <origin rpy="0.00000 0.00000 1.57080" xyz="0.13204 2.62373 1.12841"/>
      <geometry>
        <mesh filename="../meshes/stl/Cube.017.stl" scale="1.00000 0.98000 1.00000"/>
      </geometry>
    </collision>
    <collision name="obj_6_collision_2">
      <origin rpy="0.00000 0.00000 1.57080" xyz="-2.88312 2.62331 1.12841"/>
      <geometry>
        <mesh filename="../meshes/stl/Cube.018.stl" scale="1.00000 0.98000 1.00000"/>
      </geometry>
    </collision>
    <collision name="obj_6_collision_3">
      <origin rpy="0.00000 0.00000 1.57080" xyz="-1.37420 2.62395 0.94081"/>
      <geometry>
        <mesh filename="../meshes/stl/Cube.019.stl" scale="2.00000 6.08000 1.00000"/>
      </geometry>
    </collision>
    <inertial>
      <inertia ixx="0.66551" ixy="0.00000" ixz="0.00000" iyy="0.04842" iyz="0.00000" izz="0.65895"/>
      <origin rpy="0.00000 0.00000 0.00000" xyz="-1.37550 2.62500 1.04590"/>
      <mass value="0.50000"/>
    </inertial>
    <visual name="obj_6">
      <material name="None"/>
      <origin rpy="0.00000 0.00000 1.57080" xyz="-1.37550 2.62500 1.04590"/>
      <geometry>
        <mesh filename="../meshes/stl/luban-lock-sliding.005.stl" scale="0.05000 0.05000 0.05000"/>
      </geometry>
    </visual>
  </link>
  <link name="obj_7_virtual_z_link">
    <inertial>
      <inertia ixx="0.00100" ixy="0.00000" ixz="0.00000" iyy="0.00100" iyz="0.00000" izz="0.00100"/>
      <origin rpy="0.00000 0.00000 0.00000" xyz="0.00000 0.00000 0.00000"/>
      <mass value="0.00100"/>
    </inertial>
  </link>
  <link name="obj_7_virtual_y_link">
    <inertial>
      <inertia ixx="0.00100" ixy="0.00000" ixz="0.00000" iyy="0.00100" iyz="0.00000" izz="0.00100"/>
      <origin rpy="0.00000 0.00000 0.00000" xyz="0.00000 0.00000 0.00000"/>
      <mass value="0.00100"/>
    </inertial>
  </link>
  <link name="obj_10_x_link">
    <collision name="obj_10_collision_1">
      <origin rpy="3.14159 -0.00000 -1.57080" xyz="0.13204 2.62481 2.63858"/>
      <geometry>
        <mesh filename="../meshes/stl/Cube.029.stl" scale="1.00000 0.98000 1.00000"/>
      </geometry>
    </collision>
    <collision name="obj_10_collision_2">
      <origin rpy="3.14159 -0.00000 -1.57080" xyz="-2.88312 2.62524 2.63858"/>
      <geometry>
        <mesh filename="../meshes/stl/Cube.030.stl" scale="1.00000 0.98000 1.00000"/>
      </geometry>
    </collision>
    <collision name="obj_10_collision_3">
      <origin rpy="3.14159 -0.00000 -1.57080" xyz="-1.37420 2.62460 2.82617"/>
      <geometry>
        <mesh filename="../meshes/stl/Cube.031.stl" scale="2.00000 6.08000 1.00000"/>
      </geometry>
    </collision>
    <inertial>
      <inertia ixx="0.66551" ixy="0.00000" ixz="0.00000" iyy="0.04842" iyz="-0.00000" izz="0.65895"/>
      <origin rpy="0.00000 0.00000 0.00000" xyz="-1.37550 2.62500 2.72108"/>
      <mass value="0.50000"/>
    </inertial>
    <visual name="obj_10">
      <material name="None"/>
      <origin rpy="3.14159 -0.00000 -1.57080" xyz="-1.37550 2.62500 2.72108"/>
      <geometry>
        <mesh filename="../meshes/stl/luban-lock-sliding.009.stl" scale="0.05000 0.05000 0.05000"/>
      </geometry>
    </visual>
  </link>
  <link name="obj_7_x_link">
    <collision name="obj_7_collision_1">
      <origin rpy="3.14159 -1.57080 3.14159" xyz="-0.61451 0.74246 1.51080"/>
      <geometry>
        <mesh filename="../meshes/stl/Cube.020.stl" scale="1.00000 0.98000 1.00000"/>
      </geometry>
    </collision>
    <collision name="obj_7_collision_2">
      <origin rpy="3.14159 -1.57080 3.14159" xyz="-0.61451 3.75762 1.51038"/>
      <geometry>
        <mesh filename="../meshes/stl/Cube.021.stl" scale="1.00000 0.98000 1.00000"/>
      </geometry>
    </collision>
    <collision name="obj_7_collision_3">
      <origin rpy="3.14159 -1.57080 3.14159" xyz="-0.42691 2.24870 1.51102"/>
      <geometry>
        <mesh filename="../meshes/stl/Cube.022.stl" scale="2.00000 6.08000 1.00000"/>
      </geometry>
    </collision>
    <inertial>
      <inertia ixx="0.66551" ixy="0.00000" ixz="0.00000" iyy="0.04842" iyz="0.00000" izz="0.65895"/>
      <origin rpy="0.00000 0.00000 0.00000" xyz="-0.53200 2.25000 1.51000"/>
      <mass value="0.50000"/>
    </inertial>
    <visual name="obj_7">
      <material name="None"/>
      <origin rpy="3.14159 -1.57080 3.14159" xyz="-0.53200 2.25000 1.51000"/>
      <geometry>
        <mesh filename="../meshes/stl/luban-lock-sliding.006.stl" scale="0.05000 0.05000 0.05000"/>
      </geometry>
    </visual>
  </link>
  <link name="obj_8_virtual_z_link">
    <inertial>
      <inertia ixx="0.00100" ixy="0.00000" ixz="0.00000" iyy="0.00100" iyz="0.00000" izz="0.00100"/>
      <origin rpy="0.00000 0.00000 0.00000" xyz="0.00000 0.00000 0.00000"/>
      <mass value="0.00100"/>
    </inertial>
  </link>
  <link name="obj_8_virtual_y_link">
    <inertial>
      <inertia ixx="0.00100" ixy="0.00000" ixz="0.00000" iyy="0.00100" iyz="0.00000" izz="0.00100"/>
      <origin rpy="0.00000 0.00000 0.00000" xyz="0.00000 0.00000 0.00000"/>
      <mass value="0.00100"/>
    </inertial>
  </link>
  <link name="obj_8_x_link">
    <collision name="obj_8_collision_1">
      <origin rpy="3.14159 -1.57080 3.14159" xyz="-0.61451 0.74246 2.26072"/>
      <geometry>
        <mesh filename="../meshes/stl/Cube.023.stl" scale="1.00000 0.98000 1.00000"/>
      </geometry>
    </collision>
    <collision name="obj_8_collision_2">
      <origin rpy="3.14159 -1.57080 3.14159" xyz="-0.61451 3.75762 2.26029"/>
      <geometry>
        <mesh filename="../meshes/stl/Cube.024.stl" scale="1.00000 0.98000 1.00000"/>
      </geometry>
    </collision>
    <collision name="obj_8_collision_3">
      <origin rpy="3.14159 -1.57080 3.14159" xyz="-0.42691 2.24870 2.26093"/>
      <geometry>
        <mesh filename="../meshes/stl/Cube.025.stl" scale="2.00000 6.08000 1.00000"/>
      </geometry>
    </collision>
    <inertial>
      <inertia ixx="0.66551" ixy="-0.00000" ixz="0.00000" iyy="0.04842" iyz="0.00000" izz="0.65895"/>
      <origin rpy="0.00000 0.00000 0.00000" xyz="-0.53200 2.25000 2.26000"/>
      <mass value="0.50000"/>
    </inertial>
    <visual name="obj_8">
      <material name="None"/>
      <origin rpy="3.14159 -1.57080 3.14159" xyz="-0.53200 2.25000 2.26000"/>
      <geometry>
        <mesh filename="../meshes/stl/luban-lock-sliding.007.stl" scale="0.05000 0.05000 0.05000"/>
      </geometry>
    </visual>
  </link>
  <link name="obj_9_virtual_z_link">
    <inertial>
      <inertia ixx="0.00100" ixy="0.00000" ixz="0.00000" iyy="0.00100" iyz="0.00000" izz="0.00100"/>
      <origin rpy="0.00000 0.00000 0.00000" xyz="0.00000 0.00000 0.00000"/>
      <mass value="0.00100"/>
    </inertial>
  </link>
  <link name="obj_9_virtual_y_link">
    <inertial>
      <inertia ixx="0.00100" ixy="0.00000" ixz="0.00000" iyy="0.00100" iyz="0.00000" izz="0.00100"/>
      <origin rpy="0.00000 0.00000 0.00000" xyz="0.00000 0.00000 0.00000"/>
      <mass value="0.00100"/>
    </inertial>
  </link>
  <link name="obj_9_x_link">
    <collision name="obj_9_collision_1">
      <origin rpy="3.14159 -0.00000 -1.57080" xyz="0.13204 1.87430 2.63849"/>
      <geometry>
        <mesh filename="../meshes/stl/Cube.026.stl" scale="1.00000 0.98000 1.00000"/>
      </geometry>
    </collision>
    <collision name="obj_9_collision_2">
      <origin rpy="3.14159 -0.00000 -1.57080" xyz="-2.88312 1.87473 2.63849"/>
      <geometry>
        <mesh filename="../meshes/stl/Cube.027.stl" scale="1.00000 0.98000 1.00000"/>
      </geometry>
    </collision>
    <collision name="obj_9_collision_3">
      <origin rpy="3.14159 -0.00000 -1.57080" xyz="-1.37420 1.87409 2.82609"/>
      <geometry>
        <mesh filename="../meshes/stl/Cube.028.stl" scale="2.00000 6.08000 1.00000"/>
      </geometry>
    </collision>
    <inertial>
      <inertia ixx="0.66551" ixy="0.00000" ixz="0.00000" iyy="0.04842" iyz="-0.00000" izz="0.65895"/>
      <origin rpy="0.00000 0.00000 0.00000" xyz="-1.37550 1.87500 2.72100"/>
      <mass value="0.50000"/>
    </inertial>
    <visual name="obj_9">
      <material name="None"/>
      <origin rpy="3.14159 -0.00000 -1.57080" xyz="-1.37550 1.87500 2.72100"/>
      <geometry>
        <mesh filename="../meshes/stl/luban-lock-sliding.008.stl" scale="0.05000 0.05000 0.05000"/>
      </geometry>
    </visual>
  </link>
  <link name="obj_11_virtual_z_link">
    <inertial>
      <inertia ixx="0.00100" ixy="0.00000" ixz="0.00000" iyy="0.00100" iyz="0.00000" izz="0.00100"/>
      <origin rpy="0.00000 0.00000 0.00000" xyz="0.00000 0.00000 0.00000"/>
      <mass value="0.00100"/>
    </inertial>
  </link>
  <link name="obj_11_virtual_y_link">
    <inertial>
      <inertia ixx="0.00100" ixy="0.00000" ixz="0.00000" iyy="0.00100" iyz="0.00000" izz="0.00100"/>
      <origin rpy="0.00000 0.00000 0.00000" xyz="0.00000 0.00000 0.00000"/>
      <mass value="0.00100"/>
    </inertial>
  </link>
  <link name="obj_11_x_link">
    <collision name="obj_11_collision_1">
      <origin rpy="3.14159 1.57080 3.14159" xyz="-2.12749 0.74246 1.51073"/>
      <geometry>
        <mesh filename="../meshes/stl/Cube.032.stl" scale="1.00000 0.98000 1.00000"/>
      </geometry>
    </collision>
    <collision name="obj_11_collision_2">
      <origin rpy="3.14159 1.57080 3.14159" xyz="-2.12749 3.75762 1.51116"/>
      <geometry>
        <mesh filename="../meshes/stl/Cube.033.stl" scale="1.00000 0.98000 1.00000"/>
      </geometry>
    </collision>
    <collision name="obj_11_collision_3">
      <origin rpy="3.14159 1.57080 3.14159" xyz="-2.31509 2.24870 1.51051"/>
      <geometry>
        <mesh filename="../meshes/stl/Cube.034.stl" scale="2.00000 6.08000 1.00000"/>
      </geometry>
    </collision>
    <inertial>
      <inertia ixx="0.66551" ixy="0.00000" ixz="0.00000" iyy="0.04842" iyz="0.00000" izz="0.65895"/>
      <origin rpy="0.00000 0.00000 0.00000" xyz="-2.21000 2.25000 1.51000"/>
      <mass value="0.50000"/>
    </inertial>
    <visual name="obj_11">
      <material name="None"/>
      <origin rpy="3.14159 1.57080 3.14159" xyz="-2.21000 2.25000 1.51000"/>
      <geometry>
        <mesh filename="../meshes/stl/luban-lock-sliding.010.stl" scale="0.05000 0.05000 0.05000"/>
      </geometry>
    </visual>
  </link>
  <link name="obj_12_virtual_z_link">
    <inertial>
      <inertia ixx="0.00100" ixy="0.00000" ixz="0.00000" iyy="0.00100" iyz="0.00000" izz="0.00100"/>
      <origin rpy="0.00000 0.00000 0.00000" xyz="0.00000 0.00000 0.00000"/>
      <mass value="0.00100"/>
    </inertial>
  </link>
  <link name="obj_12_virtual_y_link">
    <inertial>
      <inertia ixx="0.00100" ixy="0.00000" ixz="0.00000" iyy="0.00100" iyz="0.00000" izz="0.00100"/>
      <origin rpy="0.00000 0.00000 0.00000" xyz="0.00000 0.00000 0.00000"/>
      <mass value="0.00100"/>
    </inertial>
  </link>
  <link name="obj_12_x_link">
    <collision name="obj_12_collision_1">
      <origin rpy="3.14159 1.57080 3.14159" xyz="-2.13455 0.74744 2.26159"/>
      <geometry>
        <mesh filename="../meshes/stl/Cube.035.stl" scale="1.00000 0.98000 1.00000"/>
      </geometry>
    </collision>
    <collision name="obj_12_collision_2">
      <origin rpy="3.14159 1.57080 3.14159" xyz="-2.13455 3.76260 2.26159"/>
      <geometry>
        <mesh filename="../meshes/stl/Cube.036.stl" scale="1.00000 0.98000 1.00000"/>
      </geometry>
    </collision>
    <collision name="obj_12_collision_3">
      <origin rpy="3.14159 1.57080 3.14159" xyz="-2.32215 2.82557 2.26327"/>
      <geometry>
        <mesh filename="../meshes/stl/Cube.037.stl" scale="2.00000 3.04000 1.00000"/>
      </geometry>
    </collision>
    <collision name="obj_12_collision_4">
      <origin rpy="3.14159 1.57080 3.14159" xyz="-2.32215 1.68440 2.07512"/>
      <geometry>
        <mesh filename="../meshes/stl/Cube.038.stl" scale="1.00000 3.04000 1.00000"/>
      </geometry>
    </collision>
    <collision name="obj_12_collision_5">
      <origin rpy="3.14159 1.57080 3.14159" xyz="-2.32215 1.30531 2.44941"/>
      <geometry>
        <mesh filename="../meshes/stl/Cube.039.stl" scale="1.00000 1.01333 1.00000"/>
      </geometry>
    </collision>
    <inertial>
      <inertia ixx="0.70645" ixy="-0.00398" ixz="0.00163" iyy="0.04381" iyz="0.00099" izz="0.70850"/>
      <origin rpy="0.00000 0.00000 0.00000" xyz="-2.20877 2.28481 2.24700"/>
      <mass value="0.50000"/>
    </inertial>
    <visual name="obj_12">
      <material name="None"/>
      <origin rpy="3.14159 1.57080 3.14159" xyz="-2.20877 2.28481 2.24700"/>
      <geometry>
        <mesh filename="../meshes/stl/luban-lock-sliding.011.stl" scale="0.05000 0.05000 0.05000"/>
      </geometry>
    </visual>
  </link>
</robot>